Workbook

Sheet Vantaggio Cliente iDea vs RID
A1: Valori di vendita energia con RID riferiti ad Impianto Fotovoltaico da 4 kWp nord Italia: Produzione 4200, autoconsumo 1470 , immissioni 2730 , consumi 1500 KWh SENZA ACCUMULO
A2: Prosumer residenziale | B2: Potenza impianto Watt | C2: Produzione annuale | D2: Immissioni in rete | E2: Consumi Utenza
B3: =G55*1000 -> 6000 | C3: =B55 -> 7200 | D3: =C55 -> 3500 | E3: =E55 -> 1800 | F3: 0 | G3: =1-F3 -> 1
A5: Tabella calcolo vendita energia immessa in rete RID / iDea
A6: Data | B6: Ora giorno | C6: PUN medio €/MWh | D6: PZO medio (GSE) €/MWh | E6: Immissioni in rete kWh/anno | F6: Immissioni valori con GSE (RID) | G6: Immissioni in rete kWh/anno con arbitraggio
A7: 2024 | B7: 1 | C7: ='Prezzi medi anno PUN e RID'!D15 -> 98.351667 | D7: ='Prezzi medi anno PUN e RID'!B49 -> 85.60631 | E7: 0 | F7: 0 | G7: 0
A8: 2024 | B8: 2 | C8: =C7 -> 98.351667 | D8: =D7 -> 85.60631 | E8: 0 | F8: 0 | G8: 0
A9: 2024 | B9: 3 | C9: =C8 -> 98.351667 | D9: =D8 -> 85.60631 | E9: 0 | F9: 0 | G9: 0
A10: 2024 | B10: 4 | C10: =C9 -> 98.351667 | D10: =D9 -> 85.60631 | E10: 0 | F10: 0 | G10: 0
A11: 2024 | B11: 5 | C11: =C10 -> 98.351667 | D11: =D10 -> 85.60631 | E11: 0 | F11: 0 | G11: 0
A12: 2024 | B12: 6 | C12: =C11 -> 98.351667 | D12: =D11 -> 85.60631 | E12: =E31/36 -> 97.222222 | F12: =((E12*D12))/1000 -> 8.3228356 | G12: =G31/36 -> 15.081389
A13: 2024 | B13: 7 | C13: ='Prezzi medi anno PUN e RID'!C15 -> 120.31667 | D13: ='Prezzi medi anno PUN e RID'!B38 -> 98.726429 | E13: =E31/21.6 -> 162.03704 | F13: =((E13*D13))/1000 -> 15.997338 | G13: =G31/21.6 -> 25.135648
A14: 2024 | B14: 8 | C14: ='Prezzi medi anno PUN e RID'!B15 -> 113.77333 | D14: ='Prezzi medi anno PUN e RID'!B27 -> 103.70845 | E14: =E31/13.5 -> 259.25926 | F14: =((E14*D14))/1000 -> 26.887377 | G14: =G31/13.5 -> 40.217037
A15: 2024 | B15: 9 | C15: =C14 -> 113.77333 | D15: =D14 -> 103.70845 | E15: =E31/9 -> 388.88889 | F15: =((E15*D15))/1000 -> 40.331065 | G15: =G31/9 -> 60.325556
A16: 2024 | B16: 10 | C16: =C15 -> 113.77333 | D16: =D15 -> 103.70845 | E16: =E31/7.2 -> 486.11111 | F16: =((E16*D16))/1000 -> 50.413831 | G16: =G31/7.2 -> 75.406944
A17: 2024 | B17: 11 | C17: =C16 -> 113.77333 | D17: =D16 -> 103.70845 | E17: =E31/6.3529411 -> 550.92593 | F17: =((E17*D17))/1000 -> 57.135676 | G17: =G31/6.3529411 -> 85.461205
A18: 2024 | B18: 12 | C18: =C17 -> 113.77333 | D18: =D17 -> 103.70845 | E18: =E31/7.2 -> 486.11111 | F18: =((E18*D18))/1000 -> 50.413831 | G18: =G31/7.2 -> 75.406944
A19: 2024 | B19: 13 | C19: =C18 -> 113.77333 | D19: =D18 -> 103.70845 | E19: =E31/9 -> 388.88889 | F19: =((E19*D19))/1000 -> 40.331065 | G19: =G31/9 -> 60.325556
A20: 2024 | B20: 14 | C20: =C19 -> 113.77333 | D20: =D19 -> 103.70845 | E20: =E31/13.5 -> 259.25926 | F20: =((E20*D20))/1000 -> 26.887377 | G20: =G31/13.5 -> 40.217037
A21: 2024 | B21: 15 | C21: =C20 -> 113.77333 | D21: =D20 -> 103.70845 | E21: =E31/13.5 -> 259.25926 | F21: =((E21*D21))/1000 -> 26.887377 | G21: =G31/13.5 -> 40.217037
A22: 2024 | B22: 16 | C22: =C21 -> 113.77333 | D22: =D21 -> 103.70845 | E22: =E31/21.6 -> 162.03704 | F22: =((E22*D22))/1000 -> 16.80461 | G22: =G31/21.6 -> 25.135648
A23: 2024 | B23: 17 | C23: =C22 -> 113.77333 | D23: =D22 -> 103.70845 | E23: 0 | F23: 0 | G23: 0
A24: 2024 | B24: 18 | C24: =C23 -> 113.77333 | D24: =D23 -> 103.70845 | E24: 0 | F24: 0 | G24: 0
A25: 2024 | B25: 19 | C25: 119.48333 | D25: =D13 -> 98.726429 | E25: 0 | F25: 0 | G25: 0
A26: 2024 | B26: 20 | C26: 119.48333 | D26: =D25 -> 98.726429 | E26: 0 | F26: 0 | G26: 0
A27: 2024 | B27: 21 | C27: 119.48333 | D27: =D26 -> 98.726429 | E27: 0 | F27: 0 | G27: 0
A28: 2024 | B28: 22 | C28: 119.48333 | D28: =D27 -> 98.726429 | E28: 0 | F28: 0 | G28: 0
A29: 2024 | B29: 23 | C29: 119.48333 | D29: =D28 -> 98.726429 | E29: 0 | F29: 0 | G29: 0
A30: 2024 | B30: 24 | C30: =C9 -> 98.351667 | D30: =D8 -> 85.60631 | E30: 0 | F30: 0 | G30: 0
E31: =D3 -> 3500 | F31: =SUM(F7:F30) -> 360.41238 | G31: ='analisi accumulo prosumer'!M14 -> 542.93
A33: Modalità di consumo dei 1500 kWh del prosumer: il consumo, da valori statistici, avviene: nel 16% in fascia F1, 33% in F2 e 51% F3.
A34: Totale anno | B34: F1 16% | C34: F2 33% | D34: F3 51%
A35: =E3 -> 1800 | B35: =A35*0.16 -> 288 | C35: =A35*0.33 -> 594 | D35: =A35*0.51 -> 918
A36: Costi
A37: =B37+C37+D37 -> 194.02665 | B37: =B35*C19/1000 -> 32.76672 | C37: =C35*C26/1000 -> 70.9731 | D37: =D35*C30/1000 -> 90.28683
A38: =A37/A35 -> 0.10779258
A41: Valori economici RID vs iDea
B42: Totale Lordo | C42: Tasse | D42: Costi lettura GSE | E42: Totale Netto
A43: RID | B43: =F31 -> 360.41238 | C43: =B43*0.35 -> 126.14433 | D43: 29 | E43: =B43-C43-D43 -> 205.26805
A44: iDea | B44: ='Vantaggio Energy Cloud'!G27 -> 439.49499 | C44: 0 | D44: 0 | E44: ='Vantaggio Energy Cloud'!G27-'Vantaggio Energy Cloud'!I27-'Vantaggio Energy Cloud'!J27 -> 324.59499
...

Sheet Prezzi medi anno PUN e RID
A1: GME
A2: Mese | B2: F1 | C2: F2 | D2: F3
A3: gennaio | B3: 109.65 | C3: 105.07 | D3: 89.06
A4: febbraio | B4: 96.15 | C4: 94.92 | D4: 76.81
A5: marzo | B5: 94.93 | C5: 94.62 | D5: 81.32
A6: aprile | B6: 85.57 | C6: 101.29 | D6: 80.54
A7: maggio | B7: 94.66 | C7: 111.48 | D7: 86.24
A8: giugno | B8: 103.81 | C8: 116.16 | D8: 95.43
A9: luglio | B9: 108.67 | C9: 130.63 | D9: 104.77
A10: agosto | B10: 121.67 | C10: 147.95 | D10: 122.19
A11: sett | B11: 122.33 | C11: 131.74 | D11: 105.65
A12: ott | B12: 123.78 | C12: 126.63 | D12: 105.27
A13: nov | B13: 145.59 | C13: 137.38 | D13: 117.13
A14: dic | B14: 158.47 | C14: 145.93 | D14: 115.81
A15: Media GME | B15: =AVERAGE(B3:B14) -> 113.77333 | C15: =AVERAGE(C3:C14) -> 120.31667 | D15: =AVERAGE(D3:D14) -> 98.351667
A17: GSE
A18: Zona | B18: gen. | C18: feb. | D18: mar. | E18: apr. | F18: mag. | G18: giu. | H18: lug. | I18: ago. | J18: set. | K18: ott. | L18: nov. | M18: dic.
A19: Centro Nord | B19: 103.6 | C19: 90.82 | D19: 90.02 | E19: 76.12 | F19: 90.75 | G19: 99.92 | H19: 106.41 | I19: 116.88 | J19: 115.57 | K19: 112.93 | L19: 135.42 | M19: 147.53
A20: Centro Sud | B20: 101.75 | C20: 86 | D20: 89.59 | E20: 75.54 | F20: 88.94 | G20: 99.83 | H20: 106.35 | I20: 116.63 | J20: 113.11 | K20: 109.12 | L20: 131.33 | M20: 143.67
A21: Nord | B21: 103.42 | C21: 90.34 | D21: 89.79 | E21: 76.6 | F21: 90.5 | G21: 99.56 | H21: 105.87 | I21: 116.77 | J21: 115.73 | K21: 114.48 | L21: 136.51 | M21: 148.21
A22: Sardegna | B22: 93.82 | C22: 84.99 | D22: 63.45 | E22: 47.17 | F22: 73.37 | G22: 96.66 | H22: 86.11 | I22: 117.7 | J22: 92.67 | K22: 99.24 | L22: 132.3 | M22: 142.15 | O22: F1
A23: Sicilia | B23: 98.95 | C23: 87.45 | D23: 83.24 | E23: 73.78 | F23: 86.45 | G23: 99.14 | H23: 107.3 | I23: 117.73 | J23: 113.88 | K23: 122.28 | L23: 131.84 | M23: 143.58
A24: Sud | B24: 100.85 | C24: 85.04 | D24: 83.69 | E24: 73.86 | F24: 82.33 | G24: 99.82 | H24: 106.52 | I24: 116.72 | J24: 112.23 | K24: 111.11 | L24: 132.45 | M24: 136.77
A25: Calabria | B25: 100.51 | C25: 84.39 | D25: 83.7 | E25: 73.65 | F25: 82.78 | G25: 99.56 | H25: 106.25 | I25: 117.51 | J25: 113.39 | K25: 110.92 | L25: 130.83 | M25: 135.77
A26: media mese | B26: =AVERAGE(B19:B25) -> 100.41429 | C26: =AVERAGE(C19:C25) -> 87.004286 | D26: =AVERAGE(D19:D25) -> 83.354286 | E26: =AVERAGE(E19:E25) -> 70.96 | F26: =AVERAGE(F19:F25) -> 85.017143 | G26: =AVERAGE(G19:G25) -> 99.212857 | H26: =AVERAGE(H19:H25) -> 103.54429 | I26: =AVERAGE(I19:I25) -> 117.13429 | ... M26: =AVERAGE(M19:M25) -> 142.52571
A27: Media annuale | B27: =AVERAGE(B26:M26) -> 103.70845
A29: Zona | B29: gen. | C29: feb. | D29: mar. | E29: apr. | F29: mag. | G29: giu. | H29: lug. | I29: ago. | J29: set. | K29: ott. | L29: nov. | M29: dic.
A30: Centro Nord | B30: 96.96 | C30: 83.3 | D30: 79.34 | E30: 74.81 | F30: 83.59 | G30: 87.03 | H30: 110.08 | I30: 120.4 | J30: 102.53 | K30: 102.77 | L30: 124.84 | M30: 133.6
A31: Centro Sud | B31: 95.27 | C31: 81.03 | D31: 70.97 | E31: 74.36 | F31: 80.51 | G31: 86.41 | H31: 107.43 | I31: 116.38 | J31: 97.8 | K31: 97.34 | L31: 121.31 | M31: 126.62
A32: Nord | B32: 97.39 | C32: 94.17 | D32: 78.74 | E32: 77.19 | F32: 86.34 | G32: 91.26 | H32: 103.3 | I32: 116.36 | J32: 104.55 | K32: 108.15 | L32: 127.06 | M32: 135.07 | O32: F2
A33: Sardegna | B33: 98.87 | C33: 79.88 | D33: 69.68 | E33: 64.69 | F33: 84.24 | G33: 95.23 | H33: 122.6 | I33: 131.05 | J33: 89.91 | K33: 86.29 | L33: 121.19 | M33: 120.72
A34: Sicilia | B34: 94.51 | C34: 84.46 | D34: 68.31 | E34: 71.3 | F34: 81.52 | G34: 91.07 | H34: 106.81 | I34: 119.46 | J34: 102.98 | K34: 114.43 | L34: 126.97 | M34: 121.54
A35: Sud | B35: 98.88 | C35: 85.36 | D35: 73 | E35: 75.39 | F35: 82.16 | G35: 88.65 | H35: 107.37 | I35: 116.32 | J35: 100.82 | K35: 102.81 | L35: 124.57 | M35: 126.82
A36: Calabria | B36: 98.74 | C36: 85.73 | D36: 73.17 | E36: 74.4 | F36: 84.59 | G36: 89.96 | H36: 107.53 | I36: 118.75 | J36: 104.42 | K36: 102.18 | L36: 124.48 | M36: 124.95
A37: media mese | B37: =AVERAGE(B30:B36) -> 97.231429 | C37: =AVERAGE(C30:C36) -> 84.847143 | D37: =AVERAGE(D30:D36) -> 73.315714 | E37: =AVERAGE(E30:E36) -> 73.162857 | F37: =AVERAGE(F30:F36) -> 83.278571 | G37: =AVERAGE(G30:G36) -> 89.944286 | H37: =AVERAGE(H30:H36) -> 109.30286 | I37: =AVERAGE(I30:I36) -> 119.81714 | ... M37: =AVERAGE(M30:M36) -> 127.04571
A38: Media annuale | B38: =AVERAGE(B37:M37) -> 98.726429
A40: Zona | B40: gen. | C40: feb. | D40: mar. | E40: apr. | F40: mag. | G40: giu. | H40: lug. | I40: ago. | J40: set. | K40: ott. | L40: nov. | M40: dic.
A41: Centro Nord | B41: 85.75 | C41: 72.02 | D41: 65.74 | E41: 58.12 | F41: 60.6 | G41: 71.34 | H41: 100.45 | I41: 117.11 | J41: 85.38 | K41: 99.27 | L41: 110.43 | M41: 113.74
A42: Centro Sud | B42: 82.22 | C42: 71.65 | D42: 58.71 | E42: 56.32 | F42: 57.7 | G42: 73.58 | H42: 99.8 | I42: 116.07 | J42: 81.52 | K42: 96.29 | L42: 107.68 | M42: 112.69
A43: Nord | B43: 87.48 | C43: 72.48 | D43: 66.03 | E43: 63.32 | F43: 65.88 | G43: 76.47 | H43: 96.94 | I43: 116.14 | J43: 90.79 | K43: 100.07 | L43: 111.63 | M43: 113.47 | O43: F3
...

Sheet Vantaggio Energy Cloud
A1: Valori economici Energy Cloud iDea
A2: Data | B2: Ora | C2: €/MWh media annuale 2024 PUN | D2: Spread | E2: kWh da compensare (51% F3, 33% F2, 16% F1) al Prosumer | F2: Immissioni kWh/anno del Prosumer | G2: Valore totale ottenuto della vendita delle immissioni a valore PZO | H2: Costi sostenuti da Energy Cloud per la compensazione in bolletta dei kWh prestati: 51% F3, 33% F2, 16% F1 | I2: Ricavo trattenuto da Energy Cloud per gestione immissioni | J2: Spread applicato da Energy Cloud per la fornitura dell'energia | K2: Credito residuo prosumer da usare per Marketplace o Ulteriore sconto succesivo in bolltetta | L2: Fee Trading Batteria | M2: Fee Flessibilità | N2: Ricavi Energy Cloud
A3: 2024 | B3: 1 | C3: ='Prezzi medi anno PUN e RID'!D15 -> 98.351667 | D3: 5 | E3: ='Vantaggio Cliente iDea vs RID'!D35 -> 918 | F3: 0 | G3: 0 | H3: =(E3*C6)/1000 -> 90.28683 | I3: =(F27)*0.03 -> 105 | J3: =((D27*(E3+E10+E21))/1000)*1.1 -> 9.9 | K3: =MAX(0,G27-H27-I27-J27) -> 130.56834 | L3: =IF('Vantaggio Cliente iDea vs RID'!K55="No",'Vantaggio Cliente iDea vs RID'!M55*0.1,0) -> 0 | M3: =IF('Vantaggio Cliente iDea vs RID'!K55="Si",Flex!G25,0) -> 67.323305 | N3: =(M27+I27+L3+J3)*0.95 -> 173.11214
A4: 2024 | B4: 2 | C4: =C3 -> 98.351667 | D4: =D3 -> 5 | F4: 0 | G4: 0
A5: 2024 | B5: 3 | C5: =C4 -> 98.351667 | D5: =D4 -> 5 | F5: 0 | G5: 0
A6: 2024 | B6: 4 | C6: =C5 -> 98.351667 | D6: =D5 -> 5 | F6: 0 | G6: 0
A7: 2024 | B7: 5 | C7: =C6 -> 98.351667 | D7: =D6 -> 5 | F7: 0 | G7: 0
A8: 2024 | B8: 6 | C8: =C7 -> 98.351667 | D8: =D7 -> 5 | F8: =MAX(0,((F27/36)-(F29))*'Vantaggio Cliente iDea vs RID'!G3)+('Vantaggio Cliente iDea vs RID'!G12*'Vantaggio Cliente iDea vs RID'!F3) -> 0 | G8: =(F8*C8)/1000 -> 0
A9: 2024 | B9: 7 | C9: ='Prezzi medi anno PUN e RID'!C15 -> 120.31667 | D9: =D8 -> 5 | F9: =(((F27/21.6)+((30*4*'Vantaggio Cliente iDea vs RID'!I55)))*'Vantaggio Cliente iDea vs RID'!G3)+('Vantaggio Cliente iDea vs RID'!G13*'Vantaggio Cliente iDea vs RID'!F3) -> 1602.037 | G9: =(F9*C9)/1000 -> 192.75176
A10: 2024 | B10: 8 | C10: ='Prezzi medi anno PUN e RID'!B15 -> 113.77333 | D10: =D9 -> 5 | E10: ='Vantaggio Cliente iDea vs RID'!B35 -> 288 | F10: =(((F27/13.5)-(F29))*'Vantaggio Cliente iDea vs RID'!G3)+('Vantaggio Cliente iDea vs RID'!G14*'Vantaggio Cliente iDea vs RID'!F3) -> 99.259259 | G10: =(F10*C10)/1000 -> 11.293057 | H10: =E10*C15/1000 -> 32.76672
A11: 2024 | B11: 9 | C11: =C10 -> 113.77333 | D11: =D10 -> 5 | F11: =(((F27/9)-(F29))*'Vantaggio Cliente iDea vs RID'!G3)+('Vantaggio Cliente iDea vs RID'!G15*'Vantaggio Cliente iDea vs RID'!F3) -> 228.88889 | G11: =(F11*C11)/1000 -> 26.041452
A12: 2024 | B12: 10 | C12: =C11 -> 113.77333 | D12: =D11 -> 5 | F12: =(((F27/7.2)-(F29))*'Vantaggio Cliente iDea vs RID'!G3)+('Vantaggio Cliente iDea vs RID'!G16*'Vantaggio Cliente iDea vs RID'!F3) -> 326.11111 | G12: =(F12*C12)/1000 -> 37.102748
A13: 2024 | B13: 11 | C13: =C12 -> 113.77333 | D13: =D12 -> 5 | F13: =(((F27/6.3529411)-(F29))*'Vantaggio Cliente iDea vs RID'!G3)+('Vantaggio Cliente iDea vs RID'!G17*'Vantaggio Cliente iDea vs RID'!F3) -> 390.92593 | G13: =(F13*C13)/1000 -> 44.476946
A14: 2024 | B14: 12 | C14: =C13 -> 113.77333 | D14: =D13 -> 5 | F14: =(((F27/7.2)-F29)*'Vantaggio Cliente iDea vs RID'!G3)+('Vantaggio Cliente iDea vs RID'!G18*'Vantaggio Cliente iDea vs RID'!F3) -> 326.11111 | G14: =(F14*C14)/1000 -> 37.102748
A15: 2024 | B15: 13 | C15: =C14 -> 113.77333 | D15: =D14 -> 5 | F15: =(((F27/9)-(F29))*'Vantaggio Cliente iDea vs RID'!G3)+('Vantaggio Cliente iDea vs RID'!G19*'Vantaggio Cliente iDea vs RID'!F3) -> 228.88889 | G15: =(F15*C15)/1000 -> 26.041452
A16: 2024 | B16: 14 | C16: =C15 -> 113.77333 | D16: =D15 -> 5 | F16: =(((F27/13.5)-(F29))*'Vantaggio Cliente iDea vs RID'!G3)+('Vantaggio Cliente iDea vs RID'!G20*'Vantaggio Cliente iDea vs RID'!F3) -> 99.259259 | G16: =(F16*C16)/1000 -> 11.293057
A17: 2024 | B17: 15 | C17: =C16 -> 113.77333 | D17: =D16 -> 5 | F17: =(((F27/13.5)-(F29))*'Vantaggio Cliente iDea vs RID'!G3)+('Vantaggio Cliente iDea vs RID'!G21*'Vantaggio Cliente iDea vs RID'!F3) -> 99.259259 | G17: =(F17*C17)/1000 -> 11.293057
A18: 2024 | B18: 16 | C18: =C17 -> 113.77333 | D18: =D17 -> 5 | F18: =(((F27/21.6)-(F29))*'Vantaggio Cliente iDea vs RID'!G3)+('Vantaggio Cliente iDea vs RID'!G22*'Vantaggio Cliente iDea vs RID'!F3) -> 2.037037 | G18: =(F18*C18)/1000 -> 0.23176049
A19: 2024 | B19: 17 | C19: =C18 -> 113.77333 | D19: =D18 -> 5 | F19: 0 | G19: =(F19*C19)/1000 -> 0
A20: 2024 | B20: 18 | C20: =C19 -> 113.77333 | D20: =D19 -> 5 | F20: 0 | G20: =(F20*C20)/1000 -> 0
A21: 2024 | B21: 19 | C21: 119.48333 | D21: =D20 -> 5 | E21: ='Vantaggio Cliente iDea vs RID'!C35 -> 594 | F21: =(((F30*(1-'Vantaggio Cliente iDea vs RID'!F3))*('Vantaggio Cliente iDea vs RID'!G3)+('Vantaggio Cliente iDea vs RID'!F3*'analisi accumulo prosumer'!D24))*'Vantaggio Cliente iDea vs RID'!G3)+('analisi accumulo prosumer'!E24*'Vantaggio Cliente iDea vs RID'!F3) -> 350.4 | G21: =(F21*C21)/1000 -> 41.86696 | H21: =E21*C23/1000 -> 70.9731
A22: 2024 | B22: 20 | C22: 119.48333 | D22: =D21 -> 5 | F22: 0 | G22: =(F22*C22)/1000 -> 0
A23: 2024 | B23: 21 | C23: 119.48333 | D23: =D22 -> 5 | F23: 0 | G23: =(F23*C23)/1000 -> 0
A24: 2024 | B24: 22 | C24: 119.48333 | D24: =D23 -> 5 | F24: 0 | G24: =(F24*C24)/1000 -> 0
A25: 2024 | B25: 23 | C25: 119.48333 | D25: =D24 -> 5 | F25: 0 | G25: =(F25*C25)/1000 -> 0
A26: 2024 | B26: 24 | C26: =C5 -> 98.351667 | D26: =D25 -> 5 | F26: 0 | G26: =(F26*C26)/1000 -> 0
D27: =AVERAGE(D3:D26) -> 5 | E27: ='Vantaggio Cliente iDea vs RID'!E3 -> 1800 | F27: ='Vantaggio Cliente iDea vs RID'!D3 -> 3500 | G27: =SUM(G3:G26) -> 439.49499 | H27: =SUM(H3:H26) -> 194.02665 | I27: =I3 -> 105 | J27: =J3 -> 9.9 | K27: =K3 -> 130.56834 | L27: =L3 -> 0 | M27: =M3 -> 67.323305 | N27: =N3 -> 173.11214
E28: Note: La restituzione (cioè prelievi da rete) sono calcolati secondo nostri dati reali: nell'esempio il prosumer consuma 51% F3, 16% F1, 33% F2. | F28: =SUM(F8:F20) -> 3402.7778 | H28: La compensazione avviene in modo dinamico, considerando i fattori di mercato dell’energia, e non può in alcun caso superare la quantità di energia ceduta al mercato.
F29: =(30*4*'Vantaggio Cliente iDea vs RID'!I55)/9 -> 160
F30: =('Vantaggio Cliente iDea vs RID'!I55*365)/12.5 -> 350.4
F31: =E27*0.16 -> 288 | G31: =-(F31*C12)/1000 -> -32.76672
F32: =E27*0.33 -> 594 | G32: =-(F32*C25)/1000 -> -70.9731
F33: =E27*0.51 -> 918 | G33: =-(F33*C26)/1000 -> -90.28683
G35: =50*-1 -> -50
F36: =F31+F32+F33 -> 1800 | G36: =F36*0.047 -> 84.6
B37: Residuo Cliente

Sheet Simulazione costi fissi
A1: mese | B1: kWh | C1: totale Bolletta | D1: energia Ivata | E1: fissi Ivati | F1: Canone | G1: Incidenza fissi totale | H1: Incidenza oneri sistema | I1: Incidenza con canone | J1: PVC | K1: Fattore incidenza in relazione energia
A2: Gennaio | B2: 744.82 | C2: 254 | D2: 152.38 | E2: 94.62 | F2: 7 | G2: =E2/(C2) -> 0.37251969 | H2: =(E2-J2)/C2 -> 0.33708661 | I2: =(F2+E2)/(C2) -> 0.40007874 | J2: 9 | K2: =(E2+F2)/D2 -> 0.66688542
A3: Febbraio | B3: 711.88 | C3: 237 | D3: 134.37 | E3: 95.37 | F3: 7 | G3: =E3/(C3) -> 0.40240506 | H3: =(E3-J3)/C3 -> 0.36443038 | I3: =(F3+E3)/(C3) -> 0.43194093 | J3: 9 | K3: =(E3+F3)/D3 -> 0.7618516
A4: marzo | B4: 454.03 | C4: 139 | D4: 76.47 | E4: 55.53 | F4: 7 | G4: =E4/(C4) -> 0.3994964 | H4: =(E4-J4)/C4 -> 0.3347482 | I4: =(F4+E4)/(C4) -> 0.44985612 | J4: 9 | K4: =(E4+F4)/D4 -> 0.81770629
A5: Aprile | B5: 350.49 | C5: 115 | D5: 61.62 | E5: 46.38 | F5: 7 | G5: =E5/(C5) -> 0.40330435 | H5: =(E5-J5)/C5 -> 0.32504348 | I5: =(F5+E5)/(C5) -> 0.46417391 | J5: 9 | K5: =(E5+F5)/D5 -> 0.86627718
A6: Maggio | B6: 49.37 | C6: 43 | D6: 15.89 | E6: 20.11 | F6: 7 | G6: =E6/(C6) -> 0.46767442 | H6: =(E6-J6)/C6 -> 0.25837209 | I6: =(F6+E6)/(C6) -> 0.63046512 | J6: 9 | K6: =(E6+F6)/D6 -> 1.7061045
A7: Giugno | B7: 35.24 | C7: 40 | D7: 14.39 | E7: 18.61 | F7: 7 | G7: =E7/(C7) -> 0.46525 | H7: =(E7-J7)/C7 -> 0.24025 | I7: =(F7+E7)/(C7) -> 0.64025 | J7: 9 | K7: =(E7+F7)/D7 -> 1.7797081
A8: Luglio | B8: 34 | C8: 58.83 | D8: 22.71 | E8: 27.12 | F8: 7 | G8: =E8/(C8) -> 0.46098929 | H8: =(E8-J8)/C8 -> 0.30800612 | I8: =(F8+E8)/(C8) -> 0.5799762 | J8: 9 | K8: =(E8+F8)/D8 -> 1.5024218
A9: Agosto | B9: 145.29 | C9: 97 | D9: 45.16 | E9: 42.84 | F9: 7 | G9: =E9/(C9) -> 0.44164948 | H9: =(E9-J9)/C9 -> 0.34886598 | I9: =(F9+E9)/(C9) -> 0.51381443 | J9: 9 | K9: =(E9+F9)/D9 -> 1.1036315
A10: Settembre | B10: 108.75 | C10: 87 | D10: 38.17 | E10: 39.84 | F10: 7 | G10: =E10/(C10) -> 0.45793103 | H10: =(E10-J10)/C10 -> 0.35448276 | I10: =(F10+E10)/(C10) -> 0.5383908 | J10: 9 | K10: =(E10+F10)/D10 -> 1.2271417
A11: Ottobre | B11: 86.95 | C11: 81 | D11: 34.34 | E11: 37.66 | F11: 7 | G11: =E11/(C11) -> 0.46493827 | H11: =(E11-J11)/C11 -> 0.35382716 | I11: =(F11+E11)/(C11) -> 0.55135802 | J11: 9 | K11: =(E11+F11)/D11 -> 1.3005242
A12: Novembre | B12: 116.13 | C12: 84 | D12: 41.84 | E12: 42.17 | F12: 7 | G12: =E12/(C12) -> 0.50202381 | H12: =(E12-J12)/C12 -> 0.39488095 | I12: =(F12+E12)/(C12) -> 0.58535714 | J12: 9 | K12: =(E12+F12)/D12 -> 1.1751912
A13: Dicembre | B13: 479.4 | C13: 180 | D13: 108.73 | E13: 71.27 | F13: 7 | G13: =E13/(C13) -> 0.39594444 | H13: =(E13-J13)/C13 -> 0.34594444 | I13: =(F13+E13)/(C13) -> 0.43483333 | J13: 9 | K13: =(E13+F13)/D13 -> 0.71985653
A14: Totale | B14: =SUM(B2:B13) -> 3316.35 | C14: =SUM(C2:C13) -> 1415.83 | D14: =SUM(D2:D13) -> 746.07 | E14: =SUM(E2:E13) -> 591.52 | F14: =SUM(F2:F13) -> 84 | I14: =AVERAGE(I2:I13) -> 0.51837456 | K14: =AVERAGE(K2:K13) -> 1.1356083
A15: Media | D15: =D14/B14 -> 0.22496721 | E15: =E14/B14 -> 0.17836477 | F15: =F14/B14 -> 0.025329052
A18: 2024
A20: mese | B20: kWh | C20: totale Bolletta | D20: energia Ivata | E20: fissi Ivati | F20: Canone | G20: Incidenza fissi totale | H20: Incidenza oneri sistema | I20: Incidenza con canone | J20: PVC | K20: Fattore incidenza in relazione energia
A21: Gennaio | B21: 744.82 | C21: 254 | D21: 152.38 | E21: 94.62 | F21: 7 | G21: =E21/(C21) -> 0.37251969 | H21: =(E21-J21)/C21 -> 0.33708661 | I21: =(F21+E21)/(C21) -> 0.40007874 | J21: 9 | K21: =(E21+F21)/D21 -> 0.66688542
A22: Febbraio | B22: 711.88 | C22: 237 | D22: 134.37 | E22: 95.37 | F22: 7 | G22: =E22/(C22) -> 0.40240506 | H22: =(E22-J22)/C22 -> 0.36443038 | I22: =(F22+E22)/(C22) -> 0.43194093 | J22: 9 | K22: =(E22+F22)/D22 -> 0.7618516
A23: marzo | B23: 454.03 | C23: 139 | D23: 76.47 | E23: 55.53 | F23: 7 | G23: =E23/(C23) -> 0.3994964 | H23: =(E23-J23)/C23 -> 0.3347482 | I23: =(F23+E23)/(C23) -> 0.44985612 | J23: 9 | K23: =(E23+F23)/D23 -> 0.81770629
A24: Aprile | B24: 350.49 | C24: 115 | D24: 61.62 | E24: 46.38 | F24: 7 | G24: =E24/(C24) -> 0.40330435 | H24: =(E24-J24)/C24 -> 0.32504348 | I24: =(F24+E24)/(C24) -> 0.46417391 | J24: 9 | K24: =(E24+F24)/D24 -> 0.86627718
A25: Maggio | B25: 49.37 | C25: 43 | D25: 15.89 | E25: 20.11 | F25: 7 | G25: =E25/(C25) -> 0.46767442 | H25: =(E25-J25)/C25 -> 0.25837209 | I25: =(F25+E25)/(C25) -> 0.63046512 | J25: 9 | K25: =(E25+F25)/D25 -> 1.7061045
A26: Giugno | B26: 35.24 | C26: 40 | D26: 14.39 | E26: 18.61 | F26: 7 | G26: =E26/(C26) -> 0.46525 | H26: =(E26-J26)/C26 -> 0.24025 | I26: =(F26+E26)/(C26) -> 0.64025 | J26: 9 | K26: =(E26+F26)/D26 -> 1.7797081
A27: Luglio | B27: 34 | C27: 58.83 | D27: 22.71 | E27: 27.12 | F27: 7 | G27: =E27/(C27) -> 0.46098929 | H27: =(E27-J27)/C27 -> 0.30800612 | I27: =(F27+E27)/(C27) -> 0.5799762 | J27: 9 | K27: =(E27+F27)/D27 -> 1.5024218
A28: Agosto | B28: 145.29 | C28: 97 | D28: 45.16 | E28: 42.84 | F28: 7 | G28: =E28/(C28) -> 0.44164948 | H28: =(E28-J28)/C28 -> 0.34886598 | I28: =(F28+E28)/(C28) -> 0.51381443 | J28: 9 | K28: =(E28+F28)/D28 -> 1.1036315
A29: Settembre | B29: 108.75 | C29: 87 | D29: 38.17 | E29: 39.84 | F29: 7 | G29: =E29/(C29) -> 0.45793103 | H29: =(E29-J29)/C29 -> 0.35448276 | I29: =(F29+E29)/(C29) -> 0.5383908 | J29: 9 | K29: =(E29+F29)/D29 -> 1.2271417
A30: Ottobre | B30: 86.95 | C30: 81 | D30: 34.34 | E30: 37.66 | F30: 7 | G30: =E30/(C30) -> 0.46493827 | H30: =(E30-J30)/C30 -> 0.35382716 | I30: =(F30+E30)/(C30) -> 0.55135802 | J30: 9 | K30: =(E30+F30)/D30 -> 1.3005242
A31: Novembre | B31: 116.13 | C31: 84 | D31: 41.84 | E31: 42.17 | F31: 7 | G31: =E31/(C31) -> 0.50202381 | H31: =(E31-J31)/C31 -> 0.39488095 | I31: =(F31+E31)/(C31) -> 0.58535714 | J31: 9 | K31: =(E31+F31)/D31 -> 1.1751912
A32: Dicembre | B32: 479.4 | C32: 180 | D32: 108.73 | E32: 71.27 | F32: 7 | G32: =E32/(C32) -> 0.39594444 | H32: =(E32-J32)/C32 -> 0.34594444 | I32: =(F32+E32)/(C32) -> 0.43483333 | J32: 9 | K32: =(E32+F32)/D32 -> 0.71985653
A33: Totale | B33: =SUM(B21:B32) -> 3316.35 | C33: =SUM(C21:C32) -> 1415.83 | D33: =SUM(D21:D32) -> 746.07 | E33: =SUM(E21:E32) -> 591.52 | F33: =SUM(F21:F32) -> 84 | I33: =AVERAGE(I21:I32) -> 0.51837456 | K33: =AVERAGE(K21:K32) -> 1.1356083
A34: Media | D34: =D33/B33 -> 0.22496721 | E34: =E33/B33 -> 0.17836477 | F34: =F33/B33 -> 0.025329052

Sheet analisi accumulo prosumer
A1: MESE | B1: MATERIA PRIMA € | C1: ALTRE VOCI SPESA ENERGIA € | D1: ONERI TRASPORTO € | E1: ONERI SISTEMA € | F1: TASSE € | G1: CONSUMO TOT KWh | H1: PRELEVATO RETE KWh | I1: PRELEVATO BATTERIA KWh | J1: AUTOCONSUMATO KWh | K1: IMMESSO BATTERIA KWh | L1: IMMESSO RETE KWh | M1: Immesso con batteria arbitraggio
A2: GEN | B2: 62.2 | C2: 48.76 | D2: 20.73 | E2: 20.4 | F2: 30.94 | G2: 951 | H2: 629.91 | I2: 108 | J2: 224 | K2: 108 | L2: 3.39 | M2: =L2 -> 3.39
A3: FEB | B3: 39.46 | C3: 37.01 | D3: 18.58 | E3: 14.7 | F3: 22.32 | G3: 779 | H3: 454.02 | I3: 147 | J3: 179 | K3: 155 | L3: 8.74 | M3: =L3 -> 8.74
A4: MAR | B4: 30.96 | C4: 30.66 | D4: 17.31 | E4: 11.36 | F4: 17.79 | G4: 763 | H4: 350.48 | I4: 176 | J4: 236 | K4: 186 | L4: 39.7 | M4: =L4 -> 39.7
A5: APR | B5: 4.23 | C5: 11.66 | D5: 13.64 | E5: 1.91 | F5: 4.38 | G5: 432 | H5: 49.35 | I5: 154 | J5: 230 | K5: 159 | L5: 333 | M5: =L5-E18 -> 7
A6: MAG | B6: 3.55 | C6: 10.84 | D6: 13.47 | E6: 1.36 | F6: 3.8 | G6: 296 | H6: 35.23 | I6: 104 | J6: 182 | K6: 101 | L6: 371 | M6: =L6-E19 -> 0
A7: GIU | B7: 0.49 | C7: 8.9 | D7: 13.1 | E7: 0.18 | F7: 2.39 | G7: 271 | H7: 4.75 | I7: 67.6 | J7: 200 | K7: 65.6 | L7: 509 | M7: =L7-E20 -> 96.6
A8: LUG | B8: 0.8 | C8: 10.06 | D8: 13.12 | E8: 0.27 | F8: 2.6 | G8: 421 | H8: 6.98 | I8: 122 | J8: 295 | K8: 149 | L8: 503 | M8: =L8-E21 -> 129
A9: AGO | B9: 0.7 | C9: 9.95 | D9: 13.11 | E9: 0.21 | F9: 2.53 | G9: 341 | H9: 5.38 | I9: 96.7 | J9: 241 | K9: 135 | L9: 525 | M9: =L9-E22 -> 125.7
A10: SET | B10: 2.94 | C10: 11.19 | D10: 13.34 | E10: 0.95 | F10: 3.45 | G10: 370 | H10: 24.39 | I10: 106 | J10: 252 | K10: 132 | L10: 176 | M10: =L10-E23 -> 0
A11: OTT | B11: 15.18 | C11: 18.18 | D11: 14.61 | E11: 4.96 | F11: 8.81 | G11: 383 | H11: 128.43 | I11: 100 | J11: 163 | K11: 110 | L11: 50.8 | M11: =L11 -> 50.8
A12: NOV | B12: 50.95 | C12: 36.31 | D12: 17.84 | E12: 15.21 | F12: 21.87 | G12: 754 | H12: 393.62 | I12: 109 | J12: 243 | K12: 132 | L12: 69.5 | M12: =L12 -> 69.5
A13: DIC | B13: 74.38 | C13: 47.54 | D13: 19.82 | E13: 21.46 | F13: 30.19 | G13: 861 | H13: 555 | I13: 52.9 | J13: 238 | K13: 78.3 | L13: 12.5 | M13: =L13 -> 12.5
H14: =SUM(H2:H13) -> 2637.54 | L14: =SUM(L2:L13) -> 2601.63 | M14: =SUM(M2:M13) -> 542.93
A16: Arbitraggio batteria
A17: Mese | B17: Utilizzo batteria kWh giorno | C17: Residuo arbitraggio | D17: Totale arbitraggio disponibile | E17: Totale arbitraggio batteria
A18: APR | B18: =I5/30 -> 5.1333333 | C18: =16-B18 -> 10.866667 | D18: =C18*30 -> 326 | E18: 326
A19: MAG | B19: =I6/31 -> 3.3548387 | C19: =16-B19 -> 12.645161 | D19: =C19*31 -> 392 | E19: 371
A20: GIU | B20: =I7/30 -> 2.2533333 | C20: =16-B20 -> 13.746667 | D20: =C20*30 -> 412.4 | E20: 412.4
A21: LUG | B21: =I8/31 -> 3.9354839 | C21: =16-B21 -> 12.064516 | D21: =C21*31 -> 374 | E21: 374
A22: AGO | B22: =I9/31 -> 3.1193548 | C22: =16-B22 -> 12.880645 | D22: =C22*31 -> 399.3 | E22: 399.3
A23: SET | B23: =I10/30 -> 3.5333333 | C23: =16-B23 -> 12.466667 | D23: =C23*30 -> 374 | E23: 176
A24: Totale | C24: =SUM(C18:C23) -> 74.670323 | D24: =SUM(D18:D23) -> 2277.7 | E24: =SUM(E18:E23) -> 2058.7
A25: Media | C25: =C24/6 -> 12.445054

Sheet Flex
A1: MiNDFlex Milano/Rozzano 2026 – Stima ricavi per storage (potenza + attivazioni)
A2: Nota: i prezzi reali dipendono dall’esito d’asta; qui i valori default sono i CAP indicati da Unareti nel PDF (link nei commenti).
A4: INPUT UTENTE (celle gialle)
A5: Potenza picco disponibile (kW) | B5: =D6 -> 4.2105263 | C5: kW
A6: Capacità energia batteria (kWh) | B6: ='Vantaggio Cliente iDea vs RID'!I56 -> 12 | C6: kWh | D6: =(B6/2.85) -> 4.2105263
A7: Quota aggiudicata / partecipazione (%) | B7: 100 | C7: %
A8: Fattore utilizzo attivazioni (%) | B8: 27 | C8: %
A9: Prezzo disponibilità (€/MW/anno) | B9: 75000 | C9: €/MW/anno
A10: Prezzo attivazione (€/MWh) | B10: 200 | C10: €/MWh
A11: Extra premialità attivazione Fase 2 (%) | B11: 25 | C11: %
A13: PARAMETRI MILANO/ROZZANO 2026 (dal PDF Unareti)
A14: Fase | B14: Periodo | C14: Ore disponibilità | D14: Fasce (sintesi) | E14: Note
A15: Fase 1 | B15: 2 feb – 29 mag 2026 | C15: 664 | D15: 14:00–22:00 (lun–ven, festivi esclusi) | E15: Schema regolamento 2025
A16: Fase 2 | B16: 1 giu – 31 dic 2026 | C16: 1556 | D16: 4h-slot; estate 3 fasce, autunno/inverno 2 fasce (lun–ven) | E16: Regolamento 2026 (previsto)
A17: Totale | C17: =C15+C16 -> 2220
A18: CALCOLO RICAVI (usa CAP come default; modificabili negli input)
A19: Potenza offerta (MW) | B19: =B5/1000 -> 0.0042105263
A20: Durata massima a P_picco (h) = Capacità (kWh) / P (kW) | B20: =IF(B5>0,B6/B5,"") -> 2.85
A22: Fase | B22: Ore | C22: Ricavo disponibilità (€) | D22: Energia attivata stimata (kWh) | E22: Ricavo attivazione (€) | F22: Ricavo totale (€) | G22: Fee Energy Cloud (€)
A23: Fase 1 | B23: =C15 -> 664 | C23: =($B$9)*($B$19)*(B23/8760)*($B$7/100) -> 23.936554 | D23: =($B$5)*B23*($B$8/100)*($B$7/100) -> 754.86316 | E23: =($B$10)*(D23/1000) -> 150.97263 | F23: =C23+E23 -> 174.90919
A24: Fase 2 | B24: =C16 -> 1556 | C24: =($B$9)*($B$19)*(B24/8760)*($B$7/100) -> 56.092286 | D24: =($B$5)*B24*($B$8/100)*($B$7/100) -> 1768.9263 | E24: =($B$10)*(D24/1000)*(1+$B$11/100) -> 442.23158 | F24: =C24+E24 -> 498.32386
A25: Totale anno (Fase 1+2) | B25: =B23+B24 -> 2220 | C25: =C23+C24 -> 80.028839 | D25: =D23+D24 -> 2523.7895 | E25: =E23+E24 -> 593.20421 | F25: =F23+F24 -> 673.23305 | G25: =F25*0.1 -> 67.323305
A27: KPI
A28: Ricavo annuo per kW di potenza (€/kW-anno) | B28: =IF($B$5>0,F25/$B$5,"") -> 159.89285
A29: Ricavo annuo per kWh di capacità (€/kWh-anno) – indicativo | B29: =IF($B$6>0,F25/$B$6,"") -> 56.102754
A31: Spiegazione formule: • Ricavo disponibilità = PrezzoDisponibilità(€/MW/anno) × PotenzaOfferta(MW) × OreDisponibilità/8760 × QuotaAggiudicata. • Energia attivata stimata = PotenzaPicco(kW) × OreDisponibilità × FattoreUtilizzo × QuotaAggiudicata. • Ricavo attivazione = PrezzoAttivazione(€/MWh) × EnergiaAttivata(MWh). Nota: il PDF parla di 'cap di prezzo' (massimo). Se vuoi una stima più realistica, sostituisci i prezzi con i valori medi/attesi delle aste.

Sheet Ricavi Tot PUN Energy
A1: Anno | B1: Aste Flex/anno | C1: Durata Aste/mese | D1: Energy Cloud | E1: Gestione batteria | F1: Valore asta €/Mw
A2: 1 | B2: 1 | C2: 3 | D2: ='Vantaggio Energy Cloud'!I27 -> 105 | E2: =(B2*(C2)*(F2/12000)*D13)/10 -> 18 | F2: 60000
A3: 2 | B3: 1 | C3: 6 | D3: =D2 -> 105 | E3: =(B3*(C3)*(F3/12000)*D13)/10 -> 36 | F3: 60000
A4: 3 | B4: 0 | C4: 0 | D4: =D3 -> 105 | E4: =(B4*(C4)*(F4/12000)*D13)/10 -> 0 | F4: 60000
A5: 4 | B5: 0 | C5: 0 | D5: =D4 -> 105 | E5: =(B5*(C5)*(F5/12000)*D13)/10 -> 0 | F5: 60000
A6: 5 | B6: 1 | C6: 3 | D6: =D5 -> 105 | E6: =(B6*(C6)*(F6/12000)*D13)/10 -> 18 | F6: 60000
A7: 6 | B7: 0 | C7: 3 | D7: =D6 -> 105 | E7: =(B7*(C7)*(F7/12000)*D13)/10 -> 0 | F7: 60000
A8: 7 | B8: 0 | C8: 3 | D8: =D7 -> 105 | E8: =(B8*(C8)*(F8/12000)*D13)/10 -> 0 | F8: 60000
A9: 8 | B9: 1 | C9: 3 | D9: =D8 -> 105 | E9: =(B9*(C9)*(F9/12000)*D13)/10 -> 18 | F9: 60000
A10: 9 | B10: 1 | C10: 12 | D10: =D9 -> 105 | E10: =(B10*(C10)*(F10/12000)*D13)/10 -> 72 | F10: 60000
C11: Tot | D11: =SUM(D2:D10)+SUM(E2:E10) -> 1107
C12: Anno | D12: =D11/9 -> 123
D13: ='Vantaggio Cliente iDea vs RID'!L54 -> 12
